Workbook

Sheet UG
B8: University of Dar es Salaam
B9: College of Information and Communication Technologies (CoICT)
B10: Department of Computer Science and Engineering
B11: First Semester University Examination - 2025/2026
B12: Invigilation Timetable - Undergraduate - Version 1.1
B13: Day | C13: Time | D13: Course | E13: Venue | F13: Invigilators
B14: Thursday 05/03/2026 | C14: 11:30-14:30 | D14: IS131 | E14: NKURUMAH HALL | F14: Dr. Wilbard Nyamwihula, Dr. Anthony Kigombola, Mr. Henry Mkama, Ephraim
D15: CS174/IS136 | E15: B106 | F15: Dr. Jimmy Mbelwa, Dr. Mahadia Tunga
E16: B302 | F16: Dr. James Chambua, Dr. Twahir Kiobya
E17: B307 | F17: Dr. Kennedy Mwakisole, Dr. Hussein Lema
E18: B310 | F18: Dr. Jacqueline Damas, Hajra
E19: D01 | F19: Dr. Hellen Maziku, Dr. Ellen Kalinga, Dr. Henrick Mwasita
C20: 15:30-18:30 | D20: IS238 | E20: B305 | F20: Dr Ally Abdulla, Mr. Simon Machera
E21: B307 | F21: Dr. Joseph Mushi, Lucas
E22: B310 | F22: Dr. Jimmy Mbelwa, Dr. Godfrey Justo
D23: IS371 | E23: B205 | F23: Dr. Masoud Mahundi, Fransica
E24: D01 | F24: Dr. Honest Kimaro, Dr. Yona Andegelile, Ms Lilian Mkonyi
B25: Friday 06/03/2026 | C25: 15:00-18:00 | D25: IS387 | E25: B305 | F25: Dr. Jimmy Mbelwa, Dr. Ally Bitebo
B27: Monday 09/03/2026 | C27: 7:30-10:30 | D27: CS243 | E27: B205 | F27: Dr. Mahadia Tunga, Mr. Simon Machera
E28: B302 | F28: Dr. Godfrey Justo, Ms Lilian Mkonyi
E29: B305 | F29: Dr. Masoud Mahundi, Lucas
E30: B310 | F30: Dr. Henrick Mwasita, Dr. Twahir Kiobya
E31: D01 | F31: Dr. James Chambua, Dr. Yona Andegelile, Hajra
B33: Tuesday 10/3/2026 | C33: 7:30-10:30 | D33: CS335 | E33: B204 | F33: Dr. Ally Bitebo, Ephraim
E34: B205 | F34: Dr Ally Abdulla, Dr. Hussein Lema
E35: B206 | F35: Dr. Mahadia Tunga, Lucas
E36: D01 | F36: Dr. Hellen Maziku, Dr. Ellen Kalinga, Fransica
D37: CS420/CS421 | E37: B302 | F37: Dr. Henrick Mwasita, Dr. Honest Kimaro
E38: B307 | F38: Dr. Anthony Kigombola, Dr. Twahir Kiobya
B40: Wednesday 11/3/2026 | C40: 7:30-10:30 | D40: IS246 | E40: B302 | F40: Dr. Godfrey Justo, Ms Lilian Mkonyi
E41: B305 | F41: Dr. Mahadia Tunga, Mr. Simon Machera
C42: 11:30-14:30 | D42: CS211 | E42: B305 | F42: Dr. Kennedy Mwakisole, Dr. Anthony Kigombola
B44: Thursday 12/3/2026 | C44: 7:30-10:30 | D44: CS336 | E44: B302 | F44: Dr. James Chambua, Dr. Anthony Kigombola
E45: B305 | F45: Dr. Hussein Lema, Dr. Henrick Mwasita
D46: IS265 | E46: B205 | F46: Dr. Hellen Maziku, Hajra
C47: 11:30-14:30 | D47: IS162 | E47: B302 | F47: Dr. Wilbard Nyamwihula, Fransica
E48: B305 | F48: Dr. Godfrey Justo, Lucas
C49: 15:30-18:30 | D49: CS433 | E49: B302 | F49: Dr. Twahir Kiobya, Ephraim
B51: Friday 13/3/2026 | C51: 7:30-10:30 | D51: IS236 | E51: B305 | F51: Dr. Yona Andegelile, Mr. Henry Mkama
E52: B307 | F52: Dr. Mahadia Tunga, Mr. Simon Machera
...

Sheet Load sharing
B2: Staff On Duty | C2: No of Inv Exams
A3: 1 | B3: Prof. Joel Mtebe
A4: 2 | B4: Dr. Honest Kimaro | C4: =COUNTIF(UG!F:F, "*"&B4&"*") -> 4
A5: 3 | B5: Dr. Ellen Kalinga | C5: =COUNTIF(UG!F:F, "*"&B5&"*") -> 4
A6: 4 | B6: Dr. Mercy Mbise
A7: 5 | B7: Dr. Fatuma Simba
A8: 6 | B8: Dr. Hellen Maziku | C8: =COUNTIF(UG!F:F, "*"&B8&"*") -> 4
A9: 7 | B9: Dr. Jimmy Mbelwa | C9: =COUNTIF(UG!F:F, "*"&B9&"*") -> 3
A10: 8 | B10: Dr. Wilbard Nyamwihula | C10: =COUNTIF(UG!F:F, "*"&B10&"*") -> 4
A11: 9 | B11: Dr. Godfrey Justo | C11: =COUNTIF(UG!F:F, "*"&B11&"*") -> 4
A12: 10 | B12: Dr Ally Abdulla | C12: =COUNTIF(UG!F:F, "*"&B12&"*") -> 4
A13: 11 | B13: Dr. Joseph Mushi | C13: =COUNTIF(UG!F:F,"*"&B13&"*") -> 4
A14: 12 | B14: Dr. Kennedy Mwakisole | C14: =COUNTIF(UG!F:F,"*"&B14&"*") -> 4
A15: 13 | B15: Dr. Leonard Peter
A16: 14 | B16: Dr. Henrick Mwasita | C16: =COUNTIF(UG!F:F,"*"&B16&"*") -> 4
A17: 15 | B17: Dr. James Chambua | C17: =COUNTIF(UG!F:F,"*"&B17&"*") -> 4
A18: 16 | B18: Dr. Masoud Mahundi | C18: =COUNTIF(UG!F:F,"*"&B18&"*") -> 4
A19: 17 | B19: Dr. Wilfred Senyoni | C19: =COUNTIF(UG!F:F,"*"&B19&"*") -> 0
A20: 18 | B20: Dr. Salome Maro
A21: 19 | B21: Dr. Mathew Mndeme
A22: 20 | B22: Dr. Yona Andegelile | C22: =COUNTIF(UG!F:F, "*"&B22&"*") -> 4
A23: 21 | B23: Dr. Daudi Mnyanghwalo
A24: 22 | B24: Dr. Mahadia Tunga | C24: =COUNTIF(UG!F:F, "*"&B24&"*") -> 5
A25: 23 | B25: Dr. Ally Bitebo | C25: =COUNTIF(UG!F:F, "*"&B25&"*") -> 3
A26: 24 | B26: Dr. Jacqueline Damas | C26: =COUNTIF(UG!F:F, "*"&B26&"*") -> 4
A27: 25 | B27: Ms Lilian Mkonyi | C27: =COUNTIF(UG!F:F, "*"&B27&"*") -> 5
A28: 26 | B28: Mr. Henry Mkama | C28: =COUNTIF(UG!F:F, "*"&B28&"*") -> 6
A29: 27 | B29: Dr. Anthony Kigombola | C29: =COUNTIF(UG!F:F, "*"&B29&"*") -> 5
A30: 28 | B30: Ephraim | C30: =COUNTIF(UG!F:F, "*"&B30&"*") -> 5
A31: 29 | B31: Hajra | C31: =COUNTIF(UG!F:F, "*"&B31&"*") -> 6
A32: 30 | B32: Fransica | C32: =COUNTIF(UG!F:F, "*"&B32&"*") -> 6
A33: 31 | B33: Lucas | C33: =COUNTIF(UG!F:F, "*"&B33&"*") -> 6
A34: 32 | B34: Dr. Twahir Kiobya | C34: =COUNTIF(UG!F:F, "*"&B34&"*") -> 5
A35: 33 | B35: Dr. Hussein Lema | C35: =COUNTIF(UG!F:F, "*"&B35&"*") -> 5
A36: 34 | B36: Mr. Simon Machera | C36: =COUNTIF(UG!F:F, "*"&B36&"*") -> 6
B40: Staff On Study Leave
A41: 1 | B41: Mr. Shaban Ramadhan Hando
A42: 2 | B42: Mr. Henry Kalisti Lamshai
A43: 3 | B43: Mr. Hassan Omary Muhomi
A44: 4 | B44: Ms. Merina Marcelino Luambano
...

Sheet Courses
A1: No | B1: Course Code | C1: Course Title
A2: 1 | B2: IS131 | C2: Introduction to Informatics and Microcomputers
A3: 2 | B3: CS151/IS139 | C3: Computer Organization and Architecture I
A4: 3 | B4: IS162 | C4: Introduction to Information Systems
A5: 4 | B5: CS174/IS136 | C5: Programming in C
A6: 5 | B6: CS211 | C6: Measurements & Instrumentation Engineering I
A7: 6 | B7: CS243 | C7: Computer Network Design and Administration
A8: 7 | B8: IS246 | C8: Principles of Computer Graphics
A9: 8 | B9: IS237 | C9: Data Abstraction and Algorithms
A10: 9 | B10: IS238 | C10: Mobile Applications Development
A11: 10 | B11: IS264 | C11: Principles of Database Systems
A12: 11 | B12: IS265 | C12: Introduction to GIS
A13: 12 | B13: IS236 | C13: Structured Systems Analysis & Design
... A25: 24 | B25: CS454 | C25: Computer Organization and Architecture III
